<?xml version="1.0" encoding="UTF-8"?>
<robot xmlns:xacro="http://www.ros.org/wiki/xacro">
    <xacro:macro name="vs050" params="platform:='ros'">
        <xacro:property name="description_pkg" value="robot_descriptions/vs050_description/"/>
        <xacro:property name="visual_mesh_type" value=".dae"/>
        <xacro:property name="collision_mesh_type" value=".stl"/>
        <xacro:if value="${platform == 'unity'}">
            <xacro:property name="description_pkg" value="vs050_description/"/>
            <xacro:property name="visual_mesh_type" value=".stl"/>
            <xacro:property name="collision_mesh_type" value=".stl"/>
        </xacro:if>
        <gazebo>
            <plugin name="gazebo_ros_control" filename="libgazebo_ros_control.so">
                <robotNamespace>/vs050</robotNamespace>
            </plugin>
        </gazebo>
        <link name="world"/>
        <joint name="joint_w" type="fixed">
            <parent link="world"/>
            <child link="base_link"/>
        </joint>
        <link name="base_link">
            <visual>
                <origin rpy="0 0 0" xyz="0 0 0"/>
                <geometry>
                    <mesh filename="package://${description_pkg}base_link${visual_mesh_type}" scale="1 1 1"/>
                </geometry>
            </visual>
            <collision>
                <origin rpy="0 0 0" xyz="0 0 0"/>
                <geometry>
                    <mesh filename="package://${description_pkg}base_link${collision_mesh_type}" scale="1 1 1"/>
                </geometry>
            </collision>
            <inertial>
                <mass value="1"/>
                <origin rpy="0.000000 0.000000 0.000000" xyz="0.000000 0.000000 0.000000"/>
                <inertia ixx="1" ixy="0" ixz="0" iyy="1" iyz="0" izz="1"/>
            </inertial>
        </link>
        <link name="J1">
            <visual>
                <origin rpy="0 0 0" xyz="0 0 0"/>
                <geometry>
                    <mesh filename="package://${description_pkg}J1${visual_mesh_type}" scale="1 1 1"/>
                </geometry>
            </visual>
            <collision>
                <origin rpy="0 0 0" xyz="0 0 0"/>
                <geometry>
                    <mesh filename="package://${description_pkg}J1${collision_mesh_type}" scale="1 1 1"/>
                </geometry>
            </collision>
            <inertial>
                <mass value="1"/>
                <origin rpy="0.000000 0.000000 0.000000" xyz="0.000000 0.000000 0.000000"/>
                <inertia ixx="1" ixy="0" ixz="0" iyy="1" iyz="0" izz="1"/>
            </inertial>
        </link>
        <joint name="joint_1" type="revolute">
            <parent link="base_link"/>
            <child link="J1"/>
            <origin rpy="0.000000 0.000000 0.000000" xyz="0.000000 0.000000 0.000000"/>
            <axis xyz="-0.000000 -0.000000 1.000000"/>
            <limit effort="1" lower="-3.14159265358979" upper="3.14159265358979" velocity="1"/>
            <dynamics damping="0" friction="0"/>
        </joint>
        <transmission name="trans_1">
            <type>transmission_interface/SimpleTransmission</type>
            <joint name="joint_1">
                <hardwareInterface>hardware_interface/PositionJointInterface</hardwareInterface>
            </joint>
            <actuator name="motor_1">
                <hardwareInterface>hardware_interface/PositionJointInterface</hardwareInterface>
                <mechanicalReduction>1</mechanicalReduction>
            </actuator>
        </transmission>
        <link name="J2">
            <visual>
                <origin rpy="0 0 0" xyz="0 0 0"/>
                <geometry>
                    <mesh filename="package://${description_pkg}J2${visual_mesh_type}" scale="1 1 1"/>
                </geometry>
            </visual>
            <collision>
                <origin rpy="0 0 0" xyz="0 0 0"/>
                <geometry>
                    <mesh filename="package://${description_pkg}J2${collision_mesh_type}" scale="1 1 1"/>
                </geometry>
            </collision>
            <inertial>
                <mass value="1"/>
                <origin rpy="0.000000 0.000000 0.000000" xyz="0.000000 0.000000 0.000000"/>
                <inertia ixx="1" ixy="0" ixz="0" iyy="1" iyz="0" izz="1"/>
            </inertial>
        </link>
        <joint name="joint_2" type="revolute">
            <parent link="J1"/>
            <child link="J2"/>
            <origin rpy="0.000000 0.000000 0.000000" xyz="0.000000 0.000000 0.345000"/>
            <axis xyz="-0.000000 1.000000 -0.000000"/>
            <limit effort="1" lower="-2.00712863979348" upper="2.0943951023932" velocity="1"/>
            <dynamics damping="0" friction="0"/>
        </joint>
        <transmission name="trans_2">
            <type>transmission_interface/SimpleTransmission</type>
            <joint name="joint_2">
                <hardwareInterface>hardware_interface/PositionJointInterface</hardwareInterface>
            </joint>
            <actuator name="motor_2">
                <hardwareInterface>hardware_interface/PositionJointInterface</hardwareInterface>
                <mechanicalReduction>1</mechanicalReduction>
            </actuator>
        </transmission>
        <link name="J3">
            <visual>
                <origin rpy="0 0 0" xyz="0 0 0"/>
                <geometry>
                    <mesh filename="package://${description_pkg}J3${visual_mesh_type}" scale="1 1 1"/>
                </geometry>
            </visual>
            <collision>
                <origin rpy="0 0 0" xyz="0 0 0"/>
                <geometry>
                    <mesh filename="package://${description_pkg}J3${collision_mesh_type}" scale="1 1 1"/>
                </geometry>
            </collision>
            <inertial>
                <mass value="1"/>
                <origin rpy="0.000000 0.000000 0.000000" xyz="0.000000 0.000000 0.000000"/>
                <inertia ixx="1" ixy="0" ixz="0" iyy="1" iyz="0" izz="1"/>
            </inertial>
        </link>
        <joint name="joint_3" type="revolute">
            <parent link="J2"/>
            <child link="J3"/>
            <origin rpy="0.000000 0.000000 0.000000" xyz="0.000000 0.000000 0.255000"/>
            <axis xyz="-0.000000 1.000000 -0.000000"/>
            <limit effort="1" lower="-2.00712863979348" upper="2.460914245312" velocity="1"/>
            <dynamics damping="0" friction="0"/>
        </joint>
        <transmission name="trans_3">
            <type>transmission_interface/SimpleTransmission</type>
            <joint name="joint_3">
                <hardwareInterface>hardware_interface/PositionJointInterface</hardwareInterface>
            </joint>
            <actuator name="motor_3">
                <hardwareInterface>hardware_interface/PositionJointInterface</hardwareInterface>
                <mechanicalReduction>1</mechanicalReduction>
            </actuator>
        </transmission>
        <link name="J4">
            <visual>
                <origin rpy="0 0 0" xyz="0 0 0"/>
                <geometry>
                    <mesh filename="package://${description_pkg}J4${visual_mesh_type}" scale="1 1 1"/>
                </geometry>
            </visual>
            <collision>
                <origin rpy="0 0 0" xyz="0 0 0"/>
                <geometry>
                    <mesh filename="package://${description_pkg}J4${collision_mesh_type}" scale="1 1 1"/>
                </geometry>
            </collision>
            <inertial>
                <mass value="1"/>
                <origin rpy="0.000000 0.000000 0.000000" xyz="0.000000 0.000000 0.000000"/>
                <inertia ixx="1" ixy="0" ixz="0" iyy="1" iyz="0" izz="1"/>
            </inertial>
        </link>
        <joint name="joint_4" type="revolute">
            <parent link="J3"/>
            <child link="J4"/>
            <origin rpy="0.000000 0.000000 0.000000" xyz="-0.010000 0.000000 -0.600000"/>
            <axis xyz="-0.000000 -0.000000 1.000000"/>
            <limit effort="1" lower="-4.71238898038469" upper="4.71238898038469" velocity="1"/>
            <dynamics damping="0" friction="0"/>
        </joint>
        <transmission name="trans_4">
            <type>transmission_interface/SimpleTransmission</type>
            <joint name="joint_4">
                <hardwareInterface>hardware_interface/PositionJointInterface</hardwareInterface>
            </joint>
            <actuator name="motor_4">
                <hardwareInterface>hardware_interface/PositionJointInterface</hardwareInterface>
                <mechanicalReduction>1</mechanicalReduction>
            </actuator>
        </transmission>
        <link name="J5">
            <visual>
                <origin rpy="0 0 0" xyz="0 0 0"/>
                <geometry>
                    <mesh filename="package://${description_pkg}J5${visual_mesh_type}" scale="1 1 1"/>
                </geometry>
            </visual>
            <collision>
                <origin rpy="0 0 0" xyz="0 0 0"/>
                <geometry>
                    <mesh filename="package://${description_pkg}J5${collision_mesh_type}" scale="1 1 1"/>
                </geometry>
            </collision>
            <inertial>
                <mass value="1"/>
                <origin rpy="0.000000 0.000000 0.000000" xyz="0.000000 0.000000 0.000000"/>
                <inertia ixx="1" ixy="0" ixz="0" iyy="1" iyz="0" izz="1"/>
            </inertial>
        </link>
        <joint name="joint_5" type="revolute">
            <parent link="J4"/>
            <child link="J5"/>
            <origin rpy="0.000000 0.000000 0.000000" xyz="0.000000 0.000000 0.865000"/>
            <axis xyz="-0.000000 1.000000 -0.000000"/>
            <limit effort="1" lower="-2.00712863979348" upper="2.00712863979348" velocity="1"/>
            <dynamics damping="0" friction="0"/>
        </joint>
        <transmission name="trans_5">
            <type>transmission_interface/SimpleTransmission</type>
            <joint name="joint_5">
                <hardwareInterface>hardware_interface/PositionJointInterface</hardwareInterface>
            </joint>
            <actuator name="motor_5">
                <hardwareInterface>hardware_interface/PositionJointInterface</hardwareInterface>
                <mechanicalReduction>1</mechanicalReduction>
            </actuator>
        </transmission>
        <link name="J6">
            <visual>
                <origin rpy="0 0 0" xyz="0 0 0"/>
                <geometry>
                    <mesh filename="package://${description_pkg}J6${visual_mesh_type}" scale="1 1 1"/>
                </geometry>
            </visual>
            <collision>
                <origin rpy="0 0 0" xyz="0 0 0"/>
                <geometry>
                    <mesh filename="package://${description_pkg}J6${collision_mesh_type}" scale="1 1 1"/>
                </geometry>
            </collision>
            <inertial>
                <mass value="1"/>
                <origin rpy="0.000000 0.000000 0.000000" xyz="0.000000 0.000000 0.000000"/>
                <inertia ixx="1" ixy="0" ixz="0" iyy="1" iyz="0" izz="1"/>
            </inertial>
        </link>
        <joint name="joint_6" type="revolute">
            <parent link="J5"/>
            <child link="J6"/>
            <origin rpy="0.000000 0.000000 0.000000" xyz="0.000000 0.000000 0.085000"/>
            <axis xyz="-0.000000 -0.000000 1.000000"/>
            <limit effort="1" lower="-6.28318530717959" upper="6.28318530717959" velocity="1"/>
            <dynamics damping="0" friction="0"/>
        </joint>
        <transmission name="trans_6">
            <type>transmission_interface/SimpleTransmission</type>
            <joint name="joint_6">
                <hardwareInterface>hardware_interface/PositionJointInterface</hardwareInterface>
            </joint>
            <actuator name="motor_6">
                <hardwareInterface>hardware_interface/PositionJointInterface</hardwareInterface>
                <mechanicalReduction>1</mechanicalReduction>
            </actuator>
        </transmission>
    </xacro:macro>
</robot>
